Workbook

Sheet 00_ИНСТРУКЦИЯ
A1: КУКЛОВОД — Excel 1.0 | Инструкция
A3: Назначение
A4: Калькулятор предназначен для управления размером позиции и риском. Он не оценивает качество торговой идеи и не является сигналом на покупку/продажу.
A7: Цветовая легенда
A8: Жёлтый — ручной ввод
A9: Зелёный — расчёт
A10: Голубой — итог/контроль
A11: Красно-бежевый — предупреждение
A13: Ключевая логика
A14: 1. Сначала задаётся допустимый денежный риск.
A15: 2. Затем определяется цена входа и первоначальный уровень отмены сценария.
A16: 3. Из расстояния Entry → Initial SL рассчитывается 1R на единицу.
... A24: 0,75R → BE — рабочая гипотеза управления позицией. Её эффективность должна проверяться статистикой журнала.

Sheet 01_КАЛЬКУЛЯТОР
A1: КУКЛОВОД — Калькулятор позиции и R-модель
A3: A. КАПИТАЛ И ЛИМИТЫ
A4: Капитал счёта, ₽ | B4: 1000000
A5: Риск на сделку, % | B5: 0.005
A6: Максимальная доля позиции, % | B6: 0.1
A7: Максимальный размер позиции, ₽ | B7: =B4*B6 -> 100000
A9: B. ПАРАМЕТРЫ СДЕЛКИ
A10: Тикер | B10: PLZL
A11: Инструмент | B11: Полюс
A12: Направление | B12: LONG
A13: Цена входа, ₽ | B13: 1000
A14: Первоначальный Stop Loss, ₽ | B14: 920 | D14: Проверка SL
A15: ATR, ₽ | B15: 40 | D15: =IF(OR(AND(B12="LONG",B14>=B13),AND(B12="SHORT",B14<=B13)),"ОШИБКА: SL","OK") -> OK
A16: Коэффициент ATR | B16: 2
A17: Комиссия входа, % | B17: 0.0005
A18: Комиссия выхода, % | B18: 0.0005
A19: Размер тика, ₽ | B19: 0.01
A20: BE buffer, тиков | B20: 1
A21: BE trigger, R | B21: 0.75
A23: C. РАСЧЁТ РИСКА И ПОЗИЦИИ
A24: Допустимый риск, ₽ | B24: =B4*B5 -> 5000
A25: 1R на единицу, ₽ | B25: =IF(B12="LONG",B13-B14,B14-B13) -> 80
A26: Риск на единицу, % | B26: =IFERROR(B25/B13,0) -> 0.08
A27: Размер по фиксированному риску, шт. | B27: =IFERROR(B24/B25,0) -> 62.5
A28: Размер по Risk-модели, целые шт. | B28: =MAX(0,ROUNDDOWN(B27,0)) -> 62
A29: Стоимость Risk-позиции, ₽ | B29: =B28*B13 -> 62000
A30: Фактический риск Risk-позиции, ₽ | B30: =B28*B25 -> 4960
A31: Фактический риск, % | B31: =IFERROR(B30/B4,0) -> 0.00496
A32: Макс. размер по лимиту, шт. | B32: =IFERROR(B7/B13,0) -> 100
A33: Макс. размер по лимиту, целые шт. | B33: =MAX(0,ROUNDDOWN(B32,0)) -> 100
A34: Фактический размер позиции, шт. | B34: =MIN(B28,B33) -> 62
A35: Фактическая стоимость, ₽ | B35: =B34*B13 -> 62000
A36: Фактическая доля капитала, % | B36: =IFERROR(B35/B4,0) -> 0.062
A37: Фактический первоначальный риск, ₽ | B37: =B34*B25 -> 4960
A38: Фактический первоначальный риск, % | B38: =IFERROR(B37/B4,0) -> 0.00496
A40: D. ATR-МОДЕЛЬ
A41: ATR-расстояние, ₽ | B41: =B15*B16 -> 80
A42: ATR Stop, ₽ | B42: =IF(B12="LONG",B13-B41,B13+B41) -> 920
A43: Риск на единицу по ATR, ₽ | B43: =ABS(B13-B42) -> 80
A44: Размер по ATR, шт. | B44: =IFERROR(ROUNDDOWN(B24/B43,0),0) -> 62
...

Sheet 02_ПОРТФЕЛЬ
A1: КУКЛОВОД — Портфель
A3: A. СВОДКА
A4: Капитал, ₽ | B4: ='01_КАЛЬКУЛЯТОР'!B4 -> 1000000
A5: Инвестировано, ₽ | B5: =SUM(G11:G30) -> 0
A6: Свободные средства, ₽ | B6: =B4-B5 -> 1000000
A7: Открытый риск, ₽ | B7: =SUM(L11:L30) -> 0
A8: Открытый риск, % | B8: =IFERROR(B7/B4,0) -> 0
A10: Тикер | B10: Инструмент | C10: Класс | D10: Сектор | E10: Кол-во | F10: Цена | G10: Стоимость | H10: Доля | I10: Initial SL | J10: 1R/ед. | K10: Риск/ед. | L10: Риск позиции | M10: Риск % | N10: BE Trigger R | O10: Статус
G11: =IFERROR(E11*F11,0) -> 0 | H11: =IFERROR(G11/$B$4,0) -> 0 | J11: =IFERROR(ABS(F11-I11),0) -> 0 | K11: =J11 -> 0 | L11: =IFERROR(E11*K11,0) -> 0 | M11: =IFERROR(L11/$B$4,0) -> 0
G12: =IFERROR(E12*F12,0) -> 0 | H12: =IFERROR(G12/$B$4,0) -> 0 | J12: =IFERROR(ABS(F12-I12),0) -> 0 | K12: =J12 -> 0 | L12: =IFERROR(E12*K12,0) -> 0 | M12: =IFERROR(L12/$B$4,0) -> 0
G13: =IFERROR(E13*F13,0) -> 0 | H13: =IFERROR(G13/$B$4,0) -> 0 | J13: =IFERROR(ABS(F13-I13),0) -> 0 | K13: =J13 -> 0 | L13: =IFERROR(E13*K13,0) -> 0 | M13: =IFERROR(L13/$B$4,0) -> 0
G14: =IFERROR(E14*F14,0) -> 0 | H14: =IFERROR(G14/$B$4,0) -> 0 | J14: =IFERROR(ABS(F14-I14),0) -> 0 | K14: =J14 -> 0 | L14: =IFERROR(E14*K14,0) -> 0 | M14: =IFERROR(L14/$B$4,0) -> 0
G15: =IFERROR(E15*F15,0) -> 0 | H15: =IFERROR(G15/$B$4,0) -> 0 | J15: =IFERROR(ABS(F15-I15),0) -> 0 | K15: =J15 -> 0 | L15: =IFERROR(E15*K15,0) -> 0 | M15: =IFERROR(L15/$B$4,0) -> 0
G16: =IFERROR(E16*F16,0) -> 0 | H16: =IFERROR(G16/$B$4,0) -> 0 | J16: =IFERROR(ABS(F16-I16),0) -> 0 | K16: =J16 -> 0 | L16: =IFERROR(E16*K16,0) -> 0 | M16: =IFERROR(L16/$B$4,0) -> 0
G17: =IFERROR(E17*F17,0) -> 0 | H17: =IFERROR(G17/$B$4,0) -> 0 | J17: =IFERROR(ABS(F17-I17),0) -> 0 | K17: =J17 -> 0 | L17: =IFERROR(E17*K17,0) -> 0 | M17: =IFERROR(L17/$B$4,0) -> 0
G18: =IFERROR(E18*F18,0) -> 0 | H18: =IFERROR(G18/$B$4,0) -> 0 | J18: =IFERROR(ABS(F18-I18),0) -> 0 | K18: =J18 -> 0 | L18: =IFERROR(E18*K18,0) -> 0 | M18: =IFERROR(L18/$B$4,0) -> 0
G19: =IFERROR(E19*F19,0) -> 0 | H19: =IFERROR(G19/$B$4,0) -> 0 | J19: =IFERROR(ABS(F19-I19),0) -> 0 | K19: =J19 -> 0 | L19: =IFERROR(E19*K19,0) -> 0 | M19: =IFERROR(L19/$B$4,0) -> 0
G20: =IFERROR(E20*F20,0) -> 0 | H20: =IFERROR(G20/$B$4,0) -> 0 | J20: =IFERROR(ABS(F20-I20),0) -> 0 | K20: =J20 -> 0 | L20: =IFERROR(E20*K20,0) -> 0 | M20: =IFERROR(L20/$B$4,0) -> 0
G21: =IFERROR(E21*F21,0) -> 0 | H21: =IFERROR(G21/$B$4,0) -> 0 | J21: =IFERROR(ABS(F21-I21),0) -> 0 | K21: =J21 -> 0 | L21: =IFERROR(E21*K21,0) -> 0 | M21: =IFERROR(L21/$B$4,0) -> 0
G22: =IFERROR(E22*F22,0) -> 0 | H22: =IFERROR(G22/$B$4,0) -> 0 | J22: =IFERROR(ABS(F22-I22),0) -> 0 | K22: =J22 -> 0 | L22: =IFERROR(E22*K22,0) -> 0 | M22: =IFERROR(L22/$B$4,0) -> 0
... G30: =IFERROR(E30*F30,0) -> 0 | H30: =IFERROR(G30/$B$4,0) -> 0 | J30: =IFERROR(ABS(F30-I30),0) -> 0 | K30: =J30 -> 0 | L30: =IFERROR(E30*K30,0) -> 0 | M30: =IFERROR(L30/$B$4,0) -> 0

Sheet 03_РИСК
A1: КУКЛОВОД — Контроль риска
A3: Сводка
A4: Капитал, ₽ | B4: ='02_ПОРТФЕЛЬ'!B4 -> 1000000
A5: Инвестировано, ₽ | B5: ='02_ПОРТФЕЛЬ'!B5 -> 0
A6: Свободные средства, ₽ | B6: ='02_ПОРТФЕЛЬ'!B6 -> 1000000
A7: Открытый риск, ₽ | B7: ='02_ПОРТФЕЛЬ'!B7 -> 0
A8: Открытый риск, % | B8: ='02_ПОРТФЕЛЬ'!B8 -> 0
A12: Секторная концентрация
A13: Сектор | B13: Стоимость | C13: Доля капитала | D13: Открытый риск | E13: Риск %
A14: Финансы | B14: =SUMIF('02_ПОРТФЕЛЬ'!$D$11:$D$30,A14,'02_ПОРТФЕЛЬ'!$G$11:$G$30) -> 0 | C14: =IFERROR(B14/$B$4,0) -> 0 | D14: =SUMIF('02_ПОРТФЕЛЬ'!$D$11:$D$30,A14,'02_ПОРТФЕЛЬ'!$L$11:$L$30) -> 0 | E14: =IFERROR(D14/$B$4,0) -> 0
A15: Нефть и газ | B15: =SUMIF('02_ПОРТФЕЛЬ'!$D$11:$D$30,A15,'02_ПОРТФЕЛЬ'!$G$11:$G$30) -> 0 | C15: =IFERROR(B15/$B$4,0) -> 0 | D15: =SUMIF('02_ПОРТФЕЛЬ'!$D$11:$D$30,A15,'02_ПОРТФЕЛЬ'!$L$11:$L$30) -> 0 | E15: =IFERROR(D15/$B$4,0) -> 0
A16: Металлы | B16: =SUMIF('02_ПОРТФЕЛЬ'!$D$11:$D$30,A16,'02_ПОРТФЕЛЬ'!$G$11:$G$30) -> 0 | C16: =IFERROR(B16/$B$4,0) -> 0 | D16: =SUMIF('02_ПОРТФЕЛЬ'!$D$11:$D$30,A16,'02_ПОРТФЕЛЬ'!$L$11:$L$30) -> 0 | E16: =IFERROR(D16/$B$4,0) -> 0
A17: Телеком | B17: =SUMIF('02_ПОРТФЕЛЬ'!$D$11:$D$30,A17,'02_ПОРТФЕЛЬ'!$G$11:$G$30) -> 0 | C17: =IFERROR(B17/$B$4,0) -> 0 | D17: =SUMIF('02_ПОРТФЕЛЬ'!$D$11:$D$30,A17,'02_ПОРТФЕЛЬ'!$L$11:$L$30) -> 0 | E17: =IFERROR(D17/$B$4,0) -> 0
A18: IT | B18: =SUMIF('02_ПОРТФЕЛЬ'!$D$11:$D$30,A18,'02_ПОРТФЕЛЬ'!$G$11:$G$30) -> 0 | C18: =IFERROR(B18/$B$4,0) -> 0 | D18: =SUMIF('02_ПОРТФЕЛЬ'!$D$11:$D$30,A18,'02_ПОРТФЕЛЬ'!$L$11:$L$30) -> 0 | E18: =IFERROR(D18/$B$4,0) -> 0
A19: Энергетика | B19: =SUMIF('02_ПОРТФЕЛЬ'!$D$11:$D$30,A19,'02_ПОРТФЕЛЬ'!$G$11:$G$30) -> 0 | C19: =IFERROR(B19/$B$4,0) -> 0 | D19: =SUMIF('02_ПОРТФЕЛЬ'!$D$11:$D$30,A19,'02_ПОРТФЕЛЬ'!$L$11:$L$30) -> 0 | E19: =IFERROR(D19/$B$4,0) -> 0
A20: Прочее | B20: =SUMIF('02_ПОРТФЕЛЬ'!$D$11:$D$30,A20,'02_ПОРТФЕЛЬ'!$G$11:$G$30) -> 0 | C20: =IFERROR(B20/$B$4,0) -> 0 | D20: =SUMIF('02_ПОРТФЕЛЬ'!$D$11:$D$30,A20,'02_ПОРТФЕЛЬ'!$L$11:$L$30) -> 0 | E20: =IFERROR(D20/$B$4,0) -> 0

Sheet 04_СЦЕНАРИИ
A1: КУКЛОВОД — Стресс-сценарии
A3: Портфельные сценарии
A4: Сценарий | B4: Изменение | C4: P/L, ₽ | D4: Капитал после, ₽ | E4: Доходность для восстановления | F4: Комментарий
A5: Рынок −5% | B5: -0.05 | C5: ='02_ПОРТФЕЛЬ'!B5*B5 -> 0 | D5: ='02_ПОРТФЕЛЬ'!B4+C5 -> 1000000 | E5: =IFERROR(-C5/D5,0) -> 0 | F5: Стресс-сценарий
A6: Рынок −10% | B6: -0.1 | C6: ='02_ПОРТФЕЛЬ'!B5*B6 -> 0 | D6: ='02_ПОРТФЕЛЬ'!B4+C6 -> 1000000 | E6: =IFERROR(-C6/D6,0) -> 0 | F6: Стресс-сценарий
A7: Рынок −20% | B7: -0.2 | C7: ='02_ПОРТФЕЛЬ'!B5*B7 -> 0 | D7: ='02_ПОРТФЕЛЬ'!B4+C7 -> 1000000 | E7: =IFERROR(-C7/D7,0) -> 0 | F7: Стресс-сценарий
A8: Рынок −30% | B8: -0.3 | C8: ='02_ПОРТФЕЛЬ'!B5*B8 -> 0 | D8: ='02_ПОРТФЕЛЬ'!B4+C8 -> 1000000 | E8: =IFERROR(-C8/D8,0) -> 0 | F8: Стресс-сценарий
A9: Все стопы | C9: =-'02_ПОРТФЕЛЬ'!B7 -> 0 | D9: ='02_ПОРТФЕЛЬ'!B4+C9 -> 1000000 | E9: =IFERROR(-C9/D9,0) -> 0 | F9: Стоп по всему открытому риску
A12: Сценарии не являются прогнозами. Они показывают чувствительность текущего портфеля к заданному шоку.

Sheet 05_ЖУРНАЛ
A1: КУКЛОВОД — Журнал сделок и статистика R
A3: Журнал
A4: Дата | B4: Тикер | C4: Setup Type | D4: Направление | E4: Entry | F4: Initial SL | G4: Размер | H4: 1R/ед. | I4: Risk ₽ | J4: BE Trigger R | K4: BE Trigger Price | L4: BE Stop | M4: MFE R | N4: MAE R | O4: Exit | P4: Final R | Q4: Причина выхода
H5: =IFERROR(ABS(E5-F5),0) -> 0 | I5: =IFERROR(G5*H5,0) -> 0 | J5: 0.75 | K5: =IF(D5="LONG",E5+H5*J5,E5-H5*J5) -> 0
H6: =IFERROR(ABS(E6-F6),0) -> 0 | I6: =IFERROR(G6*H6,0) -> 0 | J6: 0.75 | K6: =IF(D6="LONG",E6+H6*J6,E6-H6*J6) -> 0
H7: =IFERROR(ABS(E7-F7),0) -> 0 | I7: =IFERROR(G7*H7,0) -> 0 | J7: 0.75 | K7: =IF(D7="LONG",E7+H7*J7,E7-H7*J7) -> 0
H8: =IFERROR(ABS(E8-F8),0) -> 0 | I8: =IFERROR(G8*H8,0) -> 0 | J8: 0.75 | K8: =IF(D8="LONG",E8+H8*J8,E8-H8*J8) -> 0
H9: =IFERROR(ABS(E9-F9),0) -> 0 | I9: =IFERROR(G9*H9,0) -> 0 | J9: 0.75 | K9: =IF(D9="LONG",E9+H9*J9,E9-H9*J9) -> 0
H10: =IFERROR(ABS(E10-F10),0) -> 0 | I10: =IFERROR(G10*H10,0) -> 0 | J10: 0.75 | K10: =IF(D10="LONG",E10+H10*J10,E10-H10*J10) -> 0
H11: =IFERROR(ABS(E11-F11),0) -> 0 | I11: =IFERROR(G11*H11,0) -> 0 | J11: 0.75 | K11: =IF(D11="LONG",E11+H11*J11,E11-H11*J11) -> 0
H12: =IFERROR(ABS(E12-F12),0) -> 0 | I12: =IFERROR(G12*H12,0) -> 0 | J12: 0.75 | K12: =IF(D12="LONG",E12+H12*J12,E12-H12*J12) -> 0
H13: =IFERROR(ABS(E13-F13),0) -> 0 | I13: =IFERROR(G13*H13,0) -> 0 | J13: 0.75 | K13: =IF(D13="LONG",E13+H13*J13,E13-H13*J13) -> 0
H14: =IFERROR(ABS(E14-F14),0) -> 0 | I14: =IFERROR(G14*H14,0) -> 0 | J14: 0.75 | K14: =IF(D14="LONG",E14+H14*J14,E14-H14*J14) -> 0
H15: =IFERROR(ABS(E15-F15),0) -> 0 | I15: =IFERROR(G15*H15,0) -> 0 | J15: 0.75 | K15: =IF(D15="LONG",E15+H15*J15,E15-H15*J15) -> 0
H16: =IFERROR(ABS(E16-F16),0) -> 0 | I16: =IFERROR(G16*H16,0) -> 0 | J16: 0.75 | K16: =IF(D16="LONG",E16+H16*J16,E16-H16*J16) -> 0
... H54: =IFERROR(ABS(E54-F54),0) -> 0 | I54: =IFERROR(G54*H54,0) -> 0 | J54: 0.75 | K54: =IF(D54="LONG",E54+H54*J54,E54-H54*J54) -> 0
A57: R-СТАТИСТИКА
A58: Количество сделок | B58: =COUNT(A5:A54) -> 0
A59: Средний Final R | B59: =IFERROR(AVERAGE(P5:P54),0) -> 0
A60: Медианный Final R | B60: =IFERROR(MEDIAN(P5:P54),0) -> 0
A61: Лучший Final R | B61: =IFERROR(MAX(P5:P54),0) -> 0
A62: Худший Final R | B62: =IFERROR(MIN(P5:P54),0) -> 0
A63: Количество −1R или хуже | B63: =COUNTIF(P5:P54,"<=-1") -> 0
A64: Количество −0,5R или хуже | B64: =COUNTIF(P5:P54,"<=-0.5") -> 0
A65: Количество +0,75R и выше | B65: =COUNTIF(P5:P54,">=0.75") -> 0
A66: Количество +1R и выше | B66: =COUNTIF(P5:P54,">=1") -> 0
A67: Количество +2R и выше | B67: =COUNTIF(P5:P54,">=2") -> 0

Sheet 06_СПРАВОЧНИКИ
A1: КУКЛОВОД — Справочники
A3: Направление
A4: LONG
A5: SHORT
A7: Классы активов
A8: Акция
A9: ОФЗ
A10: Корпоративная облигация
A11: Фонд денежного рынка
A12: Золото
A13: Прочее
A16: Сектора
... A33: Другое
